<sdf version='1.7'>
  <world name='default'>
    <light name='sun' type='directional'>
      <cast_shadows>1</cast_shadows>
      <pose>0 0 10 0 -0 0</pose>
      <diffuse>0.8 0.8 0.8 1</diffuse>
      <specular>0.2 0.2 0.2 1</specular>
      <attenuation>
        <range>1000</range>
        <constant>0.9</constant>
        <linear>0.01</linear>
        <quadratic>0.001</quadratic>
      </attenuation>
      <direction>-0.5 0.1 -0.9</direction>
      <spot>
        <inner_angle>0</inner_angle>
        <outer_angle>0</outer_angle>
        <falloff>0</falloff>
      </spot>
    </light>
    <gravity>0 0 -9.8</gravity>
    <magnetic_field>6e-06 2.3e-05 -4.2e-05</magnetic_field>
    <atmosphere type='adiabatic'/>
    <physics type='ode'>
      <max_step_size>0.001</max_step_size>
      <real_time_factor>1</real_time_factor>
      <real_time_update_rate>1000</real_time_update_rate>
    </physics>
    <scene>
      <ambient>0.4 0.4 0.4 1</ambient>
      <background>0.7 0.7 0.7 1</background>
      <shadows>1</shadows>
    </scene>
    <wind/>
    <spherical_coordinates>
      <surface_model>EARTH_WGS84</surface_model>
      <latitude_deg>0</latitude_deg>
      <longitude_deg>0</longitude_deg>
      <elevation>0</elevation>
      <heading_deg>0</heading_deg>
    </spherical_coordinates>
    <model name='ground_plane'>
      <static>1</static>
      <link name='link'>
        <collision name='collision'>
          <geometry>
            <plane>
              <normal>0 0 1</normal>
              <size>100 100</size>
            </plane>
          </geometry>
          <surface>
            <contact>
              <collide_bitmask>65535</collide_bitmask>
              <ode/>
            </contact>
            <friction>
              <ode>
                <mu>100</mu>
                <mu2>50</mu2>
              </ode>
              <torsional>
                <ode/>
              </torsional>
            </friction>
            <bounce/>
          </surface>
          <max_contacts>10</max_contacts>
        </collision>
        <visual name='visual'>
          <cast_shadows>0</cast_shadows>
          <geometry>
            <plane>
              <normal>0 0 1</normal>
              <size>100 100</size>
            </plane>
          </geometry>
          <material>
            <script>
              <uri>file://media/materials/scripts/gazebo.material</uri>
              <name>Gazebo/Grey</name>
            </script>
          </material>
        </visual>
        <self_collide>0</self_collide>
        <enable_wind>0</enable_wind>
        <kinematic>0</kinematic>
      </link>
      <pose>0 0 0 0 -0 0</pose>
    </model>
    <state world_name='default'>
      <sim_time>2587 867000000</sim_time>
      <real_time>145 588128477</real_time>
      <wall_time>1741247141 333554566</wall_time>
      <iterations>144094</iterations>
      <model name='drc_practice_weighted_door'>
        <pose>1.11596 0.330027 0 0 -0 0</pose>
        <scale>1 1 1</scale>
        <link name='door'>
          <pose>1.11596 0.330027 2.04 3.14159 -0 -1.01884</pose>
          <velocity>0.000146 7e-06 4e-06 -1e-06 7.6e-05 -1.2e-05</velocity>
          <acceleration>0.051454 -0.023142 -0.021774 -0.014114 0.163301 -0.172031</acceleration>
          <wrench>2.12635 -0.956342 -0.899819 0 -0 0</wrench>
        </link>
        <link name='frame'>
          <pose>1.17596 0.329527 0 0 -0 0</pose>
          <velocity>-0 0 0 -3e-06 7.4e-05 -5.9e-05</velocity>
          <acceleration>0.137663 0.011324 0.004081 -0.003335 0.141301 -0.003917</acceleration>
          <wrench>2.61559 0.215161 0.077541 0 -0 0</wrench>
        </link>
        <link name='handles'>
          <pose>1.48336 -0.400093 1.05127 0 0.084958 2.12275</pose>
          <velocity>6.2e-05 2e-06 -2.3e-05 2e-06 7.2e-05 -1.3e-05</velocity>
          <acceleration>0.002541 -0.054475 -0.048103 0.053058 0.147897 -0.087497</acceleration>
          <wrench>0.005081 -0.10895 -0.096205 0 -0 0</wrench>
        </link>
      </model>
      <model name='grey_wall'>
        <pose>-2.67854 0 0 0 -0 0</pose>
        <scale>1 1 1</scale>
        <link name='link'>
          <pose>-2.67854 0 1.4 0 -0 0</pose>
          <velocity>0 0 0 0 -0 0</velocity>
          <acceleration>0 0 0 0 -0 0</acceleration>
          <wrench>0 0 0 0 -0 0</wrench>
        </link>
      </model>
      <model name='grey_wall_clone'>
        <pose>5.87715 0 0 0 -0 0</pose>
        <scale>1 1 1</scale>
        <link name='link'>
          <pose>5.87715 0 1.4 0 -0 0</pose>
          <velocity>0 0 0 0 -0 0</velocity>
          <acceleration>0 0 0 0 -0 0</acceleration>
          <wrench>0 0 0 0 -0 0</wrench>
        </link>
      </model>
      <model name='ground_plane'>
        <pose>0 0 0 0 -0 0</pose>
        <scale>1 1 1</scale>
        <link name='link'>
          <pose>0 0 0 0 -0 0</pose>
          <velocity>0 0 0 0 -0 0</velocity>
          <acceleration>0 0 0 0 -0 0</acceleration>
          <wrench>0 0 0 0 -0 0</wrench>
        </link>
      </model>
      <light name='sun'>
        <pose>0 0 10 0 -0 0</pose>
      </light>
    </state>
    <gui fullscreen='0'>
      <camera name='user_camera'>
        <pose>2.68867 -4.88619 4.53747 0 0.613797 1.8679</pose>
        <view_controller>orbit</view_controller>
        <projection_type>perspective</projection_type>
      </camera>
    </gui>
    <model name='grey_wall'>
      <static>1</static>
      <link name='link'>
        <pose>0 0 1.4 0 -0 0</pose>
        <collision name='collision'>
          <geometry>
            <box>
              <size>7.5 0.2 2.8</size>
            </box>
          </geometry>
          <max_contacts>10</max_contacts>
          <surface>
            <contact>
              <ode/>
            </contact>
            <bounce/>
            <friction>
              <torsional>
                <ode/>
              </torsional>
              <ode/>
            </friction>
          </surface>
        </collision>
        <visual name='visual'>
          <cast_shadows>0</cast_shadows>
          <geometry>
            <box>
              <size>7.5 0.2 2.8</size>
            </box>
          </geometry>
          <material>
            <script>
              <uri>model://grey_wall/materials/scripts</uri>
              <uri>model://grey_wall/materials/textures</uri>
              <name>vrc/grey_wall</name>
            </script>
          </material>
        </visual>
        <self_collide>0</self_collide>
        <enable_wind>0</enable_wind>
        <kinematic>0</kinematic>
      </link>
      <pose>-5.93693 0.194616 0 0 -0 0</pose>
    </model>
    <model name='grey_wall_clone'>
      <static>1</static>
      <link name='link'>
        <pose>0 0 1.4 0 -0 0</pose>
        <collision name='collision'>
          <geometry>
            <box>
              <size>7.5 0.2 2.8</size>
            </box>
          </geometry>
          <max_contacts>10</max_contacts>
          <surface>
            <contact>
              <ode/>
            </contact>
            <bounce/>
            <friction>
              <torsional>
                <ode/>
              </torsional>
              <ode/>
            </friction>
          </surface>
        </collision>
        <visual name='visual'>
          <cast_shadows>0</cast_shadows>
          <geometry>
            <box>
              <size>7.5 0.2 2.8</size>
            </box>
          </geometry>
          <material>
            <script>
              <uri>model://grey_wall/materials/scripts</uri>
              <uri>model://grey_wall/materials/textures</uri>
              <name>vrc/grey_wall</name>
            </script>
          </material>
        </visual>
        <self_collide>0</self_collide>
        <enable_wind>0</enable_wind>
        <kinematic>0</kinematic>
      </link>
      <pose>-4.18628 3.15767 0 0 -0 0</pose>
    </model>
    <model name='drc_practice_weighted_door'>
      <link name='frame'>
        <pose>0.06 -0.0005 0 0 -0 0</pose>
        <inertial>
          <pose>-0.025145 -0.03429 1.0541 0 -0 0</pose>
          <mass>19</mass>
          <inertia>
            <ixx>7.04458</ixx>
            <ixy>0</ixy>
            <ixz>0</ixz>
            <iyy>7.04114</iyy>
            <iyz>0</iyz>
            <izz>0.0114511</izz>
          </inertia>
        </inertial>
        <collision name='collision_2'>
          <pose>-0.025145 -0.03429 1.0541 0 -0 0</pose>
          <geometry>
            <box>
              <size>0.05029 0.06858 2.1082</size>
            </box>
          </geometry>
          <max_contacts>10</max_contacts>
          <surface>
            <contact>
              <ode/>
            </contact>
            <bounce/>
            <friction>
              <torsional>
                <ode/>
              </torsional>
              <ode/>
            </friction>
          </surface>
        </collision>
        <visual name='visual'>
          <pose>-0.025145 -0.03429 1.0541 0 -0 0</pose>
          <geometry>
            <box>
              <size>0.05029 0.06858 2.1082</size>
            </box>
          </geometry>
          <material>
            <script>
              <uri>file://media/materials/scripts/gazebo.material</uri>
              <name>Gazebo/White</name>
            </script>
          </material>
        </visual>
        <self_collide>0</self_collide>
        <enable_wind>0</enable_wind>
        <kinematic>0</kinematic>
      </link>
      <link name='door'>
        <pose>-0 0 2.04 3.14159 -0 0</pose>
        <inertial>
          <mass>41.3256</mass>
          <pose>0.4569 0.0349 1.016 0 -0 0</pose>
          <inertia>
            <ixx>14.2263</ixx>
            <ixy>0</ixy>
            <ixz>0</ixz>
            <iyy>17.099</iyy>
            <iyz>0</iyz>
            <izz>2.88626</izz>
          </inertia>
        </inertial>
        <collision name='collision'>
          <pose>0.4569 0.0349 1.016 0 -0 0</pose>
          <geometry>
            <box>
              <size>0.9144 0.04445 2.032</size>
            </box>
          </geometry>
          <max_contacts>10</max_contacts>
          <surface>
            <contact>
              <ode/>
            </contact>
            <bounce/>
            <friction>
              <torsional>
                <ode/>
              </torsional>
              <ode/>
            </friction>
          </surface>
        </collision>
        <visual name='visual'>
          <pose>0 -0.06858 0 0 -0 0</pose>
          <geometry>
            <mesh>
              <uri>model://hinged_door/meshes/door.dae</uri>
            </mesh>
          </geometry>
        </visual>
        <self_collide>0</self_collide>
        <enable_wind>0</enable_wind>
        <kinematic>0</kinematic>
      </link>
      <link name='handles'>
        <pose>0.8144 -0.07 1.05 0 -0 3.14159</pose>
        <inertial>
          <pose>0 -0.035 0 0 -0 0</pose>
          <mass>2</mass>
          <inertia>
            <ixx>0.0110115</ixx>
            <ixy>-0</ixy>
            <ixz>-0.00647057</ixz>
            <iyy>0.0190181</iyy>
            <iyz>0</iyz>
            <izz>0.00824372</izz>
          </inertia>
        </inertial>
        <collision name='handle1_collision'>
          <pose>0.015 -0.015 0 -1.57 0 0</pose>
          <geometry>
            <mesh>
              <uri>model://door_handle/meshes/handle.dae</uri>
            </mesh>
          </geometry>
          <max_contacts>10</max_contacts>
          <surface>
            <contact>
              <ode/>
            </contact>
            <bounce/>
            <friction>
              <torsional>
                <ode/>
              </torsional>
              <ode/>
            </friction>
          </surface>
        </collision>
        <visual name='handle1_visual'>
          <pose>0.015 -0.015 0 -1.57 0 0</pose>
          <geometry>
            <mesh>
              <uri>model://door_handle/meshes/handle.dae</uri>
            </mesh>
          </geometry>
        </visual>
        <collision name='handle2_collision'>
          <pose>0.015 -0.055 0 1.57 -0 0</pose>
          <geometry>
            <mesh>
              <uri>model://door_handle/meshes/handle.dae</uri>
            </mesh>
          </geometry>
          <max_contacts>10</max_contacts>
          <surface>
            <contact>
              <ode/>
            </contact>
            <bounce/>
            <friction>
              <torsional>
                <ode/>
              </torsional>
              <ode/>
            </friction>
          </surface>
        </collision>
        <visual name='handle2_visual'>
          <pose>0.015 -0.055 0 1.57 -0 0</pose>
          <geometry>
            <mesh>
              <uri>model://door_handle/meshes/handle.dae</uri>
            </mesh>
          </geometry>
        </visual>
        <self_collide>0</self_collide>
        <enable_wind>0</enable_wind>
        <kinematic>0</kinematic>
      </link>
      <joint name='handle' type='revolute'>
        <parent>door</parent>
        <child>handles</child>
        <pose>0.015 0 0 0 -0 0</pose>
        <axis>
          <xyz expressed_in='__model__'>0 1 0</xyz>
          <limit>
            <lower>-1.58</lower>
            <upper>0</upper>
          </limit>
          <dynamics>
            <damping>1</damping>
            <friction>10</friction>
            <spring_reference>0</spring_reference>
            <spring_stiffness>0</spring_stiffness>
          </dynamics>
        </axis>
        <physics>
          <ode>
            <cfm_damping>1</cfm_damping>
            <limit>
              <cfm>0</cfm>
              <erp>0.2</erp>
            </limit>
          </ode>
        </physics>
      </joint>
      <joint name='hinge' type='revolute'>
        <parent>frame</parent>
        <child>door</child>
        <axis>
          <xyz expressed_in='__model__'>0 0 1</xyz>
          <limit>
            <lower>-1.58</lower>
            <upper>0</upper>
          </limit>
          <dynamics>
            <damping>15.5365</damping>
            <friction>15.5365</friction>
            <spring_reference>0</spring_reference>
            <spring_stiffness>0</spring_stiffness>
          </dynamics>
        </axis>
        <physics>
          <ode>
            <cfm_damping>1</cfm_damping>
            <limit>
              <cfm>0</cfm>
              <erp>0.2</erp>
            </limit>
          </ode>
        </physics>
      </joint>
      <joint name='world_joint' type='revolute'>
        <child>frame</child>
        <parent>world</parent>
        <axis>
          <limit>
            <lower>0</lower>
            <upper>0</upper>
          </limit>
          <xyz expressed_in='__model__'>0 1 0</xyz>
          <dynamics>
            <damping>1</damping>
            <spring_reference>0</spring_reference>
            <spring_stiffness>0</spring_stiffness>
          </dynamics>
        </axis>
        <physics>
          <ode>
            <cfm_damping>1</cfm_damping>
            <limit>
              <cfm>0</cfm>
              <erp>0.2</erp>
            </limit>
          </ode>
        </physics>
      </joint>
      <pose>1.11596 0.330027 0 0 -0 0</pose>
    </model>
  </world>
</sdf>
